DEBUG:openai._base_client:Encountered httpx.TimeoutException
Traceback (most recent call last):
  File "/home/runner/workspace/.pythonlibs/lib/python3.11/site-packages/httpx/_transports/default.py", line 101, in map_httpcore_exceptions
    yield
  File "/home/runner/workspace/.pythonlibs/lib/python3.11/site-packages/httpx/_transports/default.py", line 127, in __iter__
    for part in self._httpcore_stream:
  File "/home/runner/workspace/.pythonlibs/lib/python3.11/site-packages/httpcore/_sync/connection_pool.py", line 407, in __iter__
    raise exc from None
  File "/home/runner/workspace/.pythonlibs/lib/python3.11/site-packages/httpcore/_sync/connection_pool.py", line 403, in __iter__
    for part in self._stream:
  File "/home/runner/workspace/.pythonlibs/lib/python3.11/site-packages/httpcore/_sync/http11.py", line 342, in __iter__
    raise exc
  File "/home/runner/workspace/.pythonlibs/lib/python3.11/site-packages/httpcore/_sync/http11.py", line 334, in __iter__
    for chunk in self._connection._receive_response_body(**kwargs):
  File "/home/runner/workspace/.pythonlibs/lib/python3.11/site-packages/httpcore/_sync/http11.py", line 203, in _receive_response_body
    event = self._receive_event(timeout=timeout)
            ^^^^^^^^^^^^^^^^^^^^^^^^^^^^^^^^^^^^
  File "/home/runner/workspace/.pythonlibs/lib/python3.11/site-packages/httpcore/_sync/http11.py", line 217, in _receive_event
    data = self._network_stream.read(
           ^^^^^^^^^^^^^^^^^^^^^^^^^^
  File "/home/runner/workspace/.pythonlibs/lib/python3.11/site-packages/httpcore/_backends/sync.py", line 126, in read
    with map_exceptions(exc_map):
  File "/nix/store/clx0mcir7qw8zk36zbr4jra789g3knf6-python3-3.11.10/lib/python3.11/contextlib.py", line 158, in __exit__
    self.gen.throw(typ, value, traceback)
  File "/home/runner/workspace/.pythonlibs/lib/python3.11/site-packages/httpcore/_exceptions.py", line 14, in map_exceptions
    raise to_exc(exc) from exc
httpcore.ReadTimeout: The read operation timed out

The above exception was the direct cause of the following exception:

Traceback (most recent call last):
  File "/home/runner/workspace/.pythonlibs/lib/python3.11/site-packages/openai/_base_client.py", line 972, in request
    response = self._client.send(